<mujoco model="XSensStyleModel_template">
  <compiler angle="radian"/>
  <worldbody>
    <body name="humanoid" pos="0 0 0.4">
      <joint name="humanoid_free" type="free"/>
      <inertial pos="0 0 0" quat="0.820473 0.339851 -0.17592 0.424708" mass="10" diaginertia="1e-06 1e-06 1e-06"/>
      <body name="L5_f1" pos="-0.000206 0 0.098478">
        <geom size="0.069075 0.12457 0.0487345" pos="0 0 0.049743" type="box" rgba="0 1 1 1"/>
        <inertial pos="0 0 0" quat="0.820473 0.339851 -0.17592 0.424708" mass="10" diaginertia="1e-06 1e-06 1e-06"/>
        <joint name="jL5S1_rotx" pos="0 0 0" axis="1 0 0" range="-10 10" damping="0.1"/>
        <body name="L5_f2">
          <inertial pos="0 0 0" quat="0.820473 0.339851 -0.17592 0.424708" mass="1e-06" diaginertia="1e-06 1e-06 1e-06"/>
          <joint name="jL5S1_roty" pos="0 0 0" axis="0 1 0" range="-10 10" damping="0.1"/>
          <body name="L5">
            <inertial pos="0 0 0.047552" quat="0.5 0.5 -0.5 0.5" mass="6.3444" diaginertia="0.024177 0.018868 0.014872"/>
            <joint name="jL5S1_rotz" pos="0 0 0" axis="0 0 1" range="-10 10" damping="0.1"/>
            <geom size="0.069075 0.081615 0.047552" pos="0 0 0.047552" type="box" rgba="0 1 1 1"/>
            <body name="L3_f1" pos="0.000374 0 0.095104">
              <inertial pos="0 0 0" quat="0.820473 0.339851 -0.17592 0.424708" mass="1e-06" diaginertia="1e-06 1e-06 1e-06"/>
              <joint name="jL4L3_rotx" pos="0 0 0" axis="1 0 0" range="-10 10" damping="0.1"/>
              <body name="L3_f2">
                <inertial pos="0 0 0" quat="0.820473 0.339851 -0.17592 0.424708" mass="1e-06" diaginertia="1e-06 1e-06 1e-06"/>
                <joint name="jL4L3_roty" pos="0 0 0" axis="0 1 0" range="-10 10" damping="0.1"/>
                <body name="L3">
                  <inertial pos="0 0 0.042958" quat="0.5 0.5 -0.5 0.5" mass="6.3444" diaginertia="0.024177 0.017989 0.013993"/>
                  <joint name="jL4L3_rotz" pos="0 0 0" axis="0 0 1" range="-10 10" damping="0.1"/>
                  <geom size="0.069075 0.081615 0.042958" pos="0 0 0.042958" type="box" rgba="0 1 1 1"/>
                  <body name="T12_f1" pos="0 0 0.085916">
                    <inertial pos="0 0 0" quat="0.820473 0.339851 -0.17592 0.424708" mass="1e-06" diaginertia="1e-06 1e-06 1e-06"/>
                    <joint name="jL1T12_rotx" pos="0 0 0" axis="1 0 0" range="-10 10" damping="0.1"/>
                    <body name="T12_f2">
                      <inertial pos="0 0 0" quat="0.820473 0.339851 -0.17592 0.424708" mass="1e-06" diaginertia="1e-06 1e-06 1e-06"/>
                      <joint name="jL1T12_roty" pos="0 0 0" axis="0 1 0" range="-10 10" damping="0.1"/>
                      <body name="T12">
                        <inertial pos="0 0 0.042958" quat="0.5 0.5 -0.5 0.5" mass="6.3444" diaginertia="0.024177 0.017989 0.013993"/>
                        <joint name="jL1T12_rotz" pos="0 0 0" axis="0 0 1" range="-10 10" damping="0.1"/>
                        <geom size="0.069075 0.081615 0.042958" pos="0 0 0.042958" type="box" rgba="0 1 1 1"/>
                        <site name="IMU" pos="0 0 0.042958" type="box" rgba="0 1 0 1" size=".05 .05 .05"/>
                        <body name="T8_f1" pos="0 0 0.085916">
                          <inertial pos="0 0 0" quat="0.820473 0.339851 -0.17592 0.424708" mass="1e-06" diaginertia="1e-06 1e-06 1e-06"/>
                          <joint name="jT9T8_rotx" pos="0 0 0" axis="1 0 0" range="-10 10" damping="0.1"/>
                          <body name="T8_f2">
                            <inertial pos="0 0 0" quat="0.820473 0.339851 -0.17592 0.424708" mass="1e-06" diaginertia="1e-06 1e-06 1e-06"/>
                            <joint name="jT9T8_roty" pos="0 0 0" axis="0 1 0" range="-10 10" damping="0.1"/>
                            <body name="T8">
                              <inertial pos="0 0 0.059874" quat="0.5 0.5 0.5 0.5" mass="2.488" diaginertia="0.0067278 0.0043289 0.0035473"/>
                              <joint name="jT9T8_rotz" pos="0 0 0" axis="0 0 1" range="-10 10" damping="0.1"/>
                              <geom size="0.067285 0.026313 0.059875" pos="0 0 0.059874" type="box" rgba="0 1 1 1"/>
                              <body name="Neck_f1" pos="0 0 0.11975">
                                <inertial pos="0 0 0" quat="0.820473 0.339851 -0.17592 0.424708" mass="1e-06" diaginertia="1e-06 1e-06 1e-06"/>
                                <joint name="jT1C7_rotx" pos="0 0 0" axis="1 0 0" range="-10 10" damping="0.1"/>
                                <body name="Neck_f2">
                                  <inertial pos="0 0 0" quat="0.820473 0.339851 -0.17592 0.424708" mass="1e-06" diaginertia="1e-06 1e-06 1e-06"/>
                                  <joint name="jT1C7_roty" pos="0 0 0" axis="0 1 0" range="-10 10" damping="0.1"/>
                                  <body name="Neck">
                                    <inertial pos="0 0 0.044626" mass="0.7464" diaginertia="0.0006461 0.0006461 0.00030124"/>
                                    <joint name="jT1C7_rotz" pos="0 0 0" axis="0 0 1" range="-10 10" damping="0.1"/>
                                    <geom size="0.014205 0.044626" pos="0 0 0.044626" type="cylinder" rgba="0 1 1 1"/>
                                    <body name="Head_f1" pos="0.000152 0 0.089252">
                                      <inertial pos="0 0 0" quat="0.820473 0.339851 -0.17592 0.424708" mass="1e-06" diaginertia="1e-06 1e-06 1e-06"/>
                                      <joint name="jC1Head_rotx" pos="0 0 0" axis="1 0 0" range="-10 10" damping="0.1"/>
                                      <body name="Head_f2">
                                        <inertial pos="0 0 0" quat="0.820473 0.339851 -0.17592 0.424708" mass="1e-06" diaginertia="1e-06 1e-06 1e-06"/>
                                        <joint name="jC1Head_roty" pos="0 0 0" axis="0 1 0" range="-10 10" damping="0.1"/>
                                        <body name="Head">
                                          <inertial pos="0 0 0.089005" mass="2.2392" diaginertia="0.0070955 0.0070955 0.0070955"/>
                                          <joint name="jC1Head_rotz" pos="0 0 0" axis="0 0 1" range="-10 10" damping="0.1"/>
                                          <geom size="0.089005" pos="0 0 0.089005" rgba="0 1 1 1"/>
                                        </body>
                                      </body>
                                    </body>
                                  </body>
                                </body>
                              </body>
                              <body name="RightShoulder_f1" pos="0 -0.026313 0.067052">
                                <inertial pos="0 0 0" quat="0.820473 0.339851 -0.17592 0.424708" mass="1e-06" diaginertia="1e-06 1e-06 1e-06"/>
                                <joint name="jRightC7Shoulder_rotx" pos="0 0 0" axis="1 0 0" range="-10 10" damping="0.1"/>
                                <body name="RightShoulder_f2">
                                  <inertial pos="0 0 0" quat="0.820473 0.339851 -0.17592 0.424708" mass="1e-06" diaginertia="1e-06 1e-06 1e-06"/>
                                  <joint name="jRightC7Shoulder_roty" pos="0 0 0" axis="0 1 0" range="-10 10" damping="0.1"/>
                                  <body name="RightShoulder">
                                    <inertial pos="0 -0.065233 0" quat="0.707107 0.707107 0 0" mass="1.9282" diaginertia="0.0030029 0.0030029 0.00053578"/>
                                    <joint name="jRightC7Shoulder_rotz" pos="0 0 0" axis="0 0 1" range="-10 10" damping="0.1"/>
                                    <geom size="0.023574 0.065235" pos="0 -0.065233 0" quat="0.707105 0.707108 0 0" type="cylinder" rgba="0 1 1 1"/>
                                    <body name="RightUpperArm_f1" pos="0 -0.13047 0">
                                      <inertial pos="0 0 0" quat="0.820473 0.339851 -0.17592 0.424708" mass="1e-06" diaginertia="1e-06 1e-06 1e-06"/>
                                      <joint name="jRightShoulder_rotx" pos="0 0 0" axis="1 0 0" range="-10 10" damping="0.1"/>
                                      <body name="RightUpperArm_f2">
                                        <inertial pos="0 0 0" quat="0.820473 0.339851 -0.17592 0.424708" mass="1e-06" diaginertia="1e-06 1e-06 1e-06"/>
                                        <joint name="jRightShoulder_roty" pos="0 0 0" axis="0 1 0" range="-10 10" damping="0.1"/>
                                        <body name="RightUpperArm">
                                          <inertial pos="0 -0.13497 0" quat="0.707107 0.707107 0 0" mass="1.866" diaginertia="0.011736 0.011736 0.00080917"/>
                                          <joint name="jRightShoulder_rotz" pos="0 0 0" axis="0 0 1" range="-10 10" damping="0.1"/>
                                          <geom size="0.029449 0.13497" pos="0 -0.13497 0" quat="0.707105 0.707108 0 0" type="cylinder" rgba="0 1 1 1"/>
                                          <body name="RightForeArm_f1" pos="0 -0.26994 0">
                                            <inertial pos="0 0 0" quat="0.820473 0.339851 -0.17592 0.424708" mass="1e-06" diaginertia="1e-06 1e-06 1e-06"/>
                                            <joint name="jRightElbow_rotx" pos="0 0 0" axis="1 0 0" range="-10 10" damping="0.1"/>
                                            <body name="RightForeArm_f2">
                                              <inertial pos="0 0 0" quat="0.820473 0.339851 -0.17592 0.424708" mass="1e-06" diaginertia="1e-06 1e-06 1e-06"/>
                                              <joint name="jRightElbow_roty" pos="0 0 0" axis="0 1 0" range="-10 10" damping="0.1"/>
                                              <body name="RightForeArm">
                                                <inertial pos="0 -0.11124 0" quat="0.707107 0.707107 0 0" mass="1.244" diaginertia="0.0052508 0.0052508 0.00023975"/>
                                                <joint name="jRightElbow_rotz" pos="0 0 0" axis="0 0 1" range="-10 10" damping="0.1"/>
                                                <geom size="0.019633 0.111235" pos="0 -0.11124 0" quat="0.707105 0.707108 0 0" type="cylinder" rgba="0 1 1 1"/>
                                                <body name="RightHand_f1" pos="7.7e-05 -0.22247 0">
                                                  <inertial pos="0 0 0" quat="0.820473 0.339851 -0.17592 0.424708" mass="1e-06" diaginertia="1e-06 1e-06 1e-06"/>
                                                  <joint name="jRightWrist_rotx" pos="0 0 0" axis="1 0 0" range="-10 10" damping="0.1"/>
                                                  <body name="RightHand_f2">
                                                    <inertial pos="0 0 0" quat="0.820473 0.339851 -0.17592 0.424708" mass="1e-06" diaginertia="1e-06 1e-06 1e-06"/>
                                                    <joint name="jRightWrist_roty" pos="0 0 0" axis="0 1 0" range="-10 10" damping="0.1"/>
                                                    <body name="RightHand">
                                                      <inertial pos="0 -0.083588 0" quat="0.5 0.5 -0.5 0.5" mass="0.373201" diaginertia="0.0012565 0.00091813 0.00043525"/>
                                                      <joint name="jRightWrist_rotz" pos="0 0 0" axis="0 0 1" range="-10 10" damping="0.1"/>
                                                      <geom size="0.055725 0.08359 0.019633" pos="0 -0.083588 0" type="box" rgba="0 1 1 1"/>
                                                    </body>
                                                  </body>
                                                </body>
                                              </body>
                                            </body>
                                          </body>
                                        </body>
                                      </body>
                                    </body>
                                  </body>
                                </body>
                              </body>
                              <body name="LeftShoulder_f1" pos="0 0.026313 0.067052">
                                <inertial pos="0 0 0" quat="0.820473 0.339851 -0.17592 0.424708" mass="1e-06" diaginertia="1e-06 1e-06 1e-06"/>
                                <joint name="jLeftC7Shoulder_rotx" pos="0 0 0" axis="1 0 0" range="-10 10" damping="0.1"/>
                                <body name="LeftShoulder_f2">
                                  <inertial pos="0 0 0" quat="0.820473 0.339851 -0.17592 0.424708" mass="1e-06" diaginertia="1e-06 1e-06 1e-06"/>
                                  <joint name="jLeftC7Shoulder_roty" pos="0 0 0" axis="0 1 0" range="-10 10" damping="0.1"/>
                                  <body name="LeftShoulder">
                                    <inertial pos="0 0.065233 0" quat="0.707107 0.707107 0 0" mass="1.9282" diaginertia="0.0030029 0.0030029 0.00053578"/>
                                    <joint name="jLeftC7Shoulder_rotz" pos="0 0 0" axis="0 0 1" range="-10 10" damping="0.1"/>
                                    <geom size="0.023574 0.065235" pos="0 0.065233 0" quat="0.707105 0.707108 0 0" type="cylinder" rgba="0 1 1 1"/>
                                    <body name="LeftUpperArm_f1" pos="0 0.13047 0">
                                      <inertial pos="0 0 0" quat="0.820473 0.339851 -0.17592 0.424708" mass="1e-06" diaginertia="1e-06 1e-06 1e-06"/>
                                      <joint name="jLeftShoulder_rotx" pos="0 0 0" axis="1 0 0" range="-10 10" damping="0.1"/>
                                      <body name="LeftUpperArm_f2">
                                        <inertial pos="0 0 0" quat="0.820473 0.339851 -0.17592 0.424708" mass="1e-06" diaginertia="1e-06 1e-06 1e-06"/>
                                        <joint name="jLeftShoulder_roty" pos="0 0 0" axis="0 1 0" range="-10 10" damping="0.1"/>
                                        <body name="LeftUpperArm">
                                          <inertial pos="0 0.13497 0" quat="0.707107 0.707107 0 0" mass="1.866" diaginertia="0.011736 0.011736 0.00080917"/>
                                          <joint name="jLeftShoulder_rotz" pos="0 0 0" axis="0 0 1" range="-10 10" damping="0.1"/>
                                          <geom size="0.029449 0.13497" pos="0 0.13497 0" quat="0.707105 0.707108 0 0" type="cylinder" rgba="0 1 1 1"/>
                                          <body name="LeftForeArm_f1" pos="0 0.26994 0">
                                            <inertial pos="0 0 0" quat="0.820473 0.339851 -0.17592 0.424708" mass="1e-06" diaginertia="1e-06 1e-06 1e-06"/>
                                            <joint name="jLeftElbow_rotx" pos="0 0 0" axis="1 0 0" range="-10 10" damping="0.1"/>
                                            <body name="LeftForeArm_f2">
                                              <inertial pos="0 0 0" quat="0.820473 0.339851 -0.17592 0.424708" mass="1e-06" diaginertia="1e-06 1e-06 1e-06"/>
                                              <joint name="jLeftElbow_roty" pos="0 0 0" axis="0 1 0" range="-10 10" damping="0.1"/>
                                              <body name="LeftForeArm">
                                                <inertial pos="0 0.11124 0" quat="0.707107 0.707107 0 0" mass="1.244" diaginertia="0.0052508 0.0052508 0.00023975"/>
                                                <joint name="jLeftElbow_rotz" pos="0 0 0" axis="0 0 1" range="-10 10" damping="0.1"/>
                                                <geom size="0.019633 0.111235" pos="0 0.11124 0" quat="0.707105 0.707108 0 0" type="cylinder" rgba="0 1 1 1"/>
                                                <body name="LeftHand_f1" pos="7.7e-05 0.22247 0">
                                                  <inertial pos="0 0 0" quat="0.820473 0.339851 -0.17592 0.424708" mass="1e-06" diaginertia="1e-06 1e-06 1e-06"/>
                                                  <joint name="jLeftWrist_rotx" pos="0 0 0" axis="1 0 0" range="-10 10" damping="0.1"/>
                                                  <body name="LeftHand_f2">
                                                    <inertial pos="0 0 0" quat="0.820473 0.339851 -0.17592 0.424708" mass="1e-06" diaginertia="1e-06 1e-06 1e-06"/>
                                                    <joint name="jLeftWrist_roty" pos="0 0 0" axis="0 1 0" range="-10 10" damping="0.1"/>
                                                    <body name="LeftHand">
                                                      <inertial pos="0 0.083588 0" quat="0.5 0.5 -0.5 0.5" mass="0.373201" diaginertia="0.0012565 0.00091813 0.00043525"/>
                                                      <joint name="jLeftWrist_rotz" pos="0 0 0" axis="0 0 1" range="-10 10" damping="0.1"/>
                                                      <geom size="0.055725 0.08359 0.019633" pos="0 0.083588 0" type="box" rgba="0 1 1 1"/>
                                                    </body>
                                                  </body>
                                                </body>
                                              </body>
                                            </body>
                                          </body>
                                        </body>
                                      </body>
                                    </body>
                                  </body>
                                </body>
                              </body>
                            </body>
                          </body>
                        </body>
                      </body>
                    </body>
                  </body>
                </body>
              </body>
            </body>
          </body>
        </body>
      </body>
      <body name="RightUpperLeg_f1" pos="0.000103 -0.081614 0.001009">
        <inertial pos="0 0 0" quat="0.820473 0.339851 -0.17592 0.424708" mass="1e-06" diaginertia="1e-06 1e-06 1e-06"/>
        <joint name="jRightHip_rotx" pos="0 0 0" axis="1 0 0" range="-10 10" damping="0.1"/>
        <body name="RightUpperLeg_f2">
          <inertial pos="0 0 0" quat="0.820473 0.339851 -0.17592 0.424708" mass="1e-06" diaginertia="1e-06 1e-06 1e-06"/>
          <joint name="jRightHip_roty" pos="0 0 0" axis="0 1 0" range="-10 10" damping="0.1"/>
          <body name="RightUpperLeg">
            <inertial pos="0 0 -0.22449" mass="7.775" diaginertia="0.13681 0.13681 0.01241"/>
            <joint name="jRightHip_rotz" pos="0 0 0" axis="0 0 1" range="-10 10" damping="0.1"/>
            <geom size="0.0565 0.22449" pos="0 0 -0.22449" type="cylinder" rgba="0 1 1 1"/>
            <body name="RightLowerLeg_f1" pos="3.6e-05 0 -0.44898">
              <inertial pos="0 0 0" quat="0.820473 0.339851 -0.17592 0.424708" mass="1e-06" diaginertia="1e-06 1e-06 1e-06"/>
              <joint name="jRightKnee_rotx" pos="0 0 0" axis="1 0 0" range="-10 10" damping="0.1"/>
              <body name="RightLowerLeg_f2">
                <inertial pos="0 0 0" quat="0.820473 0.339851 -0.17592 0.424708" mass="1e-06" diaginertia="1e-06 1e-06 1e-06"/>
                <joint name="jRightKnee_roty" pos="0 0 0" axis="0 1 0" range="-10 10" damping="0.1"/>
                <body name="RightLowerLeg">
                  <inertial pos="0 0 -0.20304" mass="2.2703" diaginertia="0.031992 0.031992 0.0015867"/>
                  <joint name="jRightKnee_rotz" pos="0 0 0" axis="0 0 1" range="-10 10" damping="0.1"/>
                  <geom size="0.037388 0.20304" pos="0 0 -0.20304" type="cylinder" rgba="0 1 1 1"/>
                  <body name="RightFoot_f1" pos="0.000205 0 -0.40608">
                    <inertial pos="0 0 0" quat="0.820473 0.339851 -0.17592 0.424708" mass="1e-06" diaginertia="1e-06 1e-06 1e-06"/>
                    <joint name="jRightAnkle_rotx" pos="0 0 0" axis="1 0 0" range="-10 10" damping="0.1"/>
                    <body name="RightFoot_f2">
                      <inertial pos="0 0 0" quat="0.820473 0.339851 -0.17592 0.424708" mass="1e-06" diaginertia="1e-06 1e-06 1e-06"/>
                      <joint name="jRightAnkle_roty" pos="0 0 0" axis="0 1 0" range="-10 10" damping="0.1"/>
                      <body name="RightFoot">
                        <inertial pos="0.054652 0 -0.039254" quat="0.5 0.5 0.5 0.5" mass="0.8086" diaginertia="0.0025944 0.0025558 0.00079209"/>
                        <joint name="jRightAnkle_rotz" pos="0 0 0" axis="0 0 1" range="-10 10" damping="0.1"/>
                        <geom size="0.089915 0.0373875 0.0392545" pos="0.054652 0 -0.039254" type="box" rgba="0 1 1 1"/>
                        <body name="RightToe_f1" pos="0.14456 0 -0.064752">
                          <inertial pos="0 0 0" quat="0.820473 0.339851 -0.17592 0.424708" mass="1e-06" diaginertia="1e-06 1e-06 1e-06"/>
                          <joint name="jRightBallFoot_rotx" pos="0 0 0" axis="1 0 0" range="-10 10" damping="0.1"/>
                          <body name="RightToe_f2">
                            <inertial pos="0 0 0" quat="0.820473 0.339851 -0.17592 0.424708" mass="1e-06" diaginertia="1e-06 1e-06 1e-06"/>
                            <joint name="jRightBallFoot_roty" pos="0 0 0" axis="0 1 0" range="-10 10" damping="0.1"/>
                            <body name="RightToe">
                              <inertial pos="0.030086 0 0" quat="0.5 0.5 -0.5 0.5" mass="0.0933" diaginertia="7.1624e-05 4.5038e-05 2.9717e-05"/>
                              <joint name="jRightBallFoot_rotz" pos="0 0 0" axis="0 0 1" range="-10 10" damping="0.1"/>
                              <geom size="0.0300865 0.0373875 0.0070955" pos="0.030086 0 0" type="box" rgba="0 1 1 1"/>
                            </body>
                          </body>
                        </body>
                      </body>
                    </body>
                  </body>
                </body>
              </body>
            </body>
          </body>
        </body>
      </body>
      <body name="LeftUpperLeg_f1" pos="0.000103 0.081614 0.001009">
        <inertial pos="0 0 0" quat="0.820473 0.339851 -0.17592 0.424708" mass="1e-06" diaginertia="1e-06 1e-06 1e-06"/>
        <joint name="jLeftHip_rotx" pos="0 0 0" axis="1 0 0" range="-10 10" damping="0.1"/>
        <body name="LeftUpperLeg_f2">
          <inertial pos="0 0 0" quat="0.820473 0.339851 -0.17592 0.424708" mass="1e-06" diaginertia="1e-06 1e-06 1e-06"/>
          <joint name="jLeftHip_roty" pos="0 0 0" axis="0 1 0" range="-10 10" damping="0.1"/>
          <body name="LeftUpperLeg">
            <inertial pos="0 0 -0.22449" mass="7.775" diaginertia="0.13681 0.13681 0.01241"/>
            <joint name="jLeftHip_rotz" pos="0 0 0" axis="0 0 1" range="-10 10" damping="0.1"/>
            <geom size="0.0565 0.22449" pos="0 0 -0.22449" type="cylinder" rgba="0 1 1 1"/>
            <body name="LeftLowerLeg_f1" pos="3.6e-05 0 -0.44898">
              <inertial pos="0 0 0" quat="0.820473 0.339851 -0.17592 0.424708" mass="1e-06" diaginertia="1e-06 1e-06 1e-06"/>
              <joint name="jLeftKnee_rotx" pos="0 0 0" axis="1 0 0" range="-10 10" damping="0.1"/>
              <body name="LeftLowerLeg_f2">
                <inertial pos="0 0 0" quat="0.820473 0.339851 -0.17592 0.424708" mass="1e-06" diaginertia="1e-06 1e-06 1e-06"/>
                <joint name="jLeftKnee_roty" pos="0 0 0" axis="0 1 0" range="-10 10" damping="0.1"/>
                <body name="LeftLowerLeg">
                  <inertial pos="0 0 -0.20304" mass="2.2703" diaginertia="0.031992 0.031992 0.0015867"/>
                  <joint name="jLeftKnee_rotz" pos="0 0 0" axis="0 0 1" range="-10 10" damping="0.1"/>
                  <geom size="0.037388 0.20304" pos="0 0 -0.20304" type="cylinder" rgba="0 1 1 1"/>
                  <body name="LeftFoot_f1" pos="0.000205 0 -0.40608">
                    <inertial pos="0 0 0" quat="0.820473 0.339851 -0.17592 0.424708" mass="1e-06" diaginertia="1e-06 1e-06 1e-06"/>
                    <joint name="jLeftAnkle_rotx" pos="0 0 0" axis="1 0 0" range="-10 10" damping="0.1"/>
                    <body name="LeftFoot_f2">
                      <inertial pos="0 0 0" quat="0.820473 0.339851 -0.17592 0.424708" mass="1e-06" diaginertia="1e-06 1e-06 1e-06"/>
                      <joint name="jLeftAnkle_roty" pos="0 0 0" axis="0 1 0" range="-10 10" damping="0.1"/>
                      <body name="LeftFoot">
                        <inertial pos="0.054652 0 -0.039254" quat="0.5 0.5 0.5 0.5" mass="0.8086" diaginertia="0.0025944 0.0025558 0.00079209"/>
                        <joint name="jLeftAnkle_rotz" pos="0 0 0" axis="0 0 1" range="-10 10" damping="0.1"/>
                        <geom size="0.089915 0.0373875 0.0392545" pos="0.054652 0 -0.039254" type="box" rgba="0 1 1 1"/>
                        <site name="foot_LLB" pos="0.054652 0 -0.08" type="box" rgba="0 1 0 1" size="0.08 0.0275 0.02"/>
                        <body name="LeftToe_f1" pos="0.14456 0 -0.064752">
                          <inertial pos="0 0 0" quat="0.820473 0.339851 -0.17592 0.424708" mass="1e-06" diaginertia="1e-06 1e-06 1e-06"/>
                          <joint name="jLeftBallFoot_rotx" pos="0 0 0" axis="1 0 0" range="-10 10" damping="0.1"/>
                          <body name="LeftToe_f2">
                            <inertial pos="0 0 0" quat="0.820473 0.339851 -0.17592 0.424708" mass="1e-06" diaginertia="1e-06 1e-06 1e-06"/>
                            <joint name="jLeftBallFoot_roty" pos="0 0 0" axis="0 1 0" range="-10 10" damping="0.1"/>
                            <body name="LeftToe">
                              <inertial pos="0.030086 0 0" quat="0.5 0.5 -0.5 0.5" mass="0.0933" diaginertia="7.1624e-05 4.5038e-05 2.9717e-05"/>
                              <joint name="jLeftBallFoot_rotz" pos="0 0 0" axis="0 0 1" range="-10 10" damping="0.1"/>
                              <geom size="0.0300865 0.0373875 0.0070955" pos="0.030086 0 0" type="box" rgba="0 1 1 1"/>
                            </body>
                          </body>
                        </body>
                      </body>
                    </body>
                  </body>
                </body>
              </body>
            </body>
          </body>
        </body>
      </body>
    </body>
  </worldbody>
  
  <actuator>
    <motor name="jL5S1_roty" joint="jLeftBallFoot_rotz" gear="10"/>
    <motor name="jLeftBallFoot_roty" joint="jLeftBallFoot_roty" gear="10"/>
    <motor name="jLeftBallFoot_rotx" joint="jLeftBallFoot_rotx" gear="10"/>
    <motor name="jLeftAnkle_rotz" joint="jLeftAnkle_rotz" gear="10"/>
  </actuator>

  <sensor>
    <accelerometer name="accelerometer" site="IMU"/>
    <velocimeter name="velocimeter" site="IMU"/>
    <gyro name="gyro" site="IMU"/>
    <touch name="pressure_LLB" site="foot_LLB"/>
    <jointpos name="jLeftBallFoot_rotz" joint="jLeftBallFoot_rotz"/>
  </sensor>
  

</mujoco>
