<?xml version="1.0" encoding="utf-8"?>
<!-- This URDF was automatically created by SolidWorks to URDF Exporter! Originally created by Stephen Brawner (brawner@gmail.com) 
     Commit Version: 1.6.0-4-g7f85cfe  Build Version: 1.6.7995.38578
     For more information, please see http://wiki.ros.org/sw_urdf_exporter -->
<robot
  name="new_humanoid1">
  <link
    name="torso">
    <inertial>
      <origin
        xyz="0.185727602896482 0.115554053768311 0.0253849821773398"
        rpy="0 0 0" />
      <mass
        value="1.12683815772725" />
      <inertia
        ixx="0.00119648391422406"
        ixy="5.45777149558184E-08"
        ixz="6.28348061841414E-08"
        iyy="0.00125191979529046"
        iyz="-3.93310665299735E-05"
        izz="0.00164335970694054" />
    </inertial>
    <visual>
      <origin
        xyz="0 0 0"
        rpy="0 0 0" />
      <geometry>
        <mesh
          filename="package://new_humanoid1/meshes/torso.stl" />
      </geometry>
      <material
        name="">
        <color
          rgba="0.898039215686275 0.898039215686275 0.898039215686275 1" />
      </material>
    </visual>
    <collision>
      <origin
        xyz="0 0 0"
        rpy="0 0 0" />
      <geometry>
        <mesh
          filename="package://new_humanoid1/meshes/torso.stl" />
      </geometry>
    </collision>
  </link>
  <link
    name="left_shoulder_roll_link">
    <inertial>
      <origin
        xyz="0.00060569419118689 -0.0120163616763335 0.0186305200300296"
        rpy="0 0 0" />
      <mass
        value="0.0517508412627564" />
      <inertia
        ixx="1.42018834257987E-05"
        ixy="6.55738875727244E-10"
        ixz="3.44104880054116E-07"
        iyy="1.00733338221696E-05"
        iyz="-8.43769836336127E-10"
        izz="1.42018183782065E-05" />
    </inertial>
    <visual>
      <origin
        xyz="0 0 0"
        rpy="0 0 0" />
      <geometry>
        <mesh
          filename="package://new_humanoid1/meshes/left_shoulder_roll_link.stl" />
      </geometry>
      <material
        name="">
        <color
          rgba="0.792156862745098 0.819607843137255 0.933333333333333 1" />
      </material>
    </visual>
    <collision>
      <origin
        xyz="0 0 0"
        rpy="0 0 0" />
      <geometry>
        <mesh
          filename="package://new_humanoid1/meshes/left_shoulder_roll_link.stl" />
      </geometry>
    </collision>
  </link>
  <joint
    name="left_shoulder_roll_joint"
    type="continuous">
    <origin
      xyz="0.31335 -0.0091897 0.17689"
      rpy="1.5708 -0.0027388 0" />
    <parent
      link="torso" />
    <child
      link="left_shoulder_roll_link" />
    <axis
      xyz="0 0 1" />
  </joint>
  <link
    name="left_shoulder_pitch_link">
    <inertial>
      <origin
        xyz="-5.93784624658075E-06 -0.0552442357547616 -1.91630156187728E-10"
        rpy="0 0 0" />
      <mass
        value="0.0745776056411012" />
      <inertia
        ixx="3.48173987795426E-05"
        ixy="-8.34312072832988E-13"
        ixz="2.53800153511982E-13"
        iyy="2.00988483782087E-05"
        iyz="3.34728462710614E-12"
        izz="2.30395766663295E-05" />
    </inertial>
    <visual>
      <origin
        xyz="0 0 0"
        rpy="0 0 0" />
      <geometry>
        <mesh
          filename="package://new_humanoid1/meshes/left_shoulder_pitch_link.stl" />
      </geometry>
      <material
        name="">
        <color
          rgba="1 1 1 1" />
      </material>
    </visual>
    <collision>
      <origin
        xyz="0 0 0"
        rpy="0 0 0" />
      <geometry>
        <mesh
          filename="package://new_humanoid1/meshes/left_shoulder_pitch_link.stl" />
      </geometry>
    </collision>
  </link>
  <joint
    name="left_shoulder_pitch_joint"
    type="continuous">
    <origin
      xyz="0 -0.024 0.018"
      rpy="1.5708 -1.5122 -1.5708" />
    <parent
      link="left_shoulder_roll_link" />
    <child
      link="left_shoulder_pitch_link" />
    <axis
      xyz="0 0 1" />
  </joint>
  <link
    name="left_forearm_pitch_link">
    <inertial>
      <origin
        xyz="0.000238558370971198 -0.0331072824909753 8.27912349677454E-05"
        rpy="0 0 0" />
      <mass
        value="0.0942790389863083" />
      <inertia
        ixx="3.34845374036422E-05"
        ixy="-2.55512530818678E-07"
        ixz="-5.23896995390395E-09"
        iyy="1.67702180449322E-05"
        iyz="-1.0308628459388E-09"
        izz="3.00632539502804E-05" />
    </inertial>
    <visual>
      <origin
        xyz="0 0 0"
        rpy="0 0 0" />
      <geometry>
        <mesh
          filename="package://new_humanoid1/meshes/left_forearm_pitch_link.stl" />
      </geometry>
      <material
        name="">
        <color
          rgba="1 1 1 1" />
      </material>
    </visual>
    <collision>
      <origin
        xyz="0 0 0"
        rpy="0 0 0" />
      <geometry>
        <mesh
          filename="package://new_humanoid1/meshes/left_forearm_pitch_link.stl" />
      </geometry>
    </collision>
  </link>
  <joint
    name="left_forearm_pitch_joint"
    type="continuous">
    <origin
      xyz="0 -0.11049 0"
      rpy="2.4953 -1.5708 -2.5197" />
    <parent
      link="left_shoulder_pitch_link" />
    <child
      link="left_forearm_pitch_link" />
    <axis
      xyz="1 0 0" />
  </joint>
  <link
    name="right_shoulder_roll_link">
    <inertial>
      <origin
        xyz="0.000605143284141685 -0.0120163616742932 0.018630520030378"
        rpy="0 0 0" />
      <mass
        value="0.0517508412605279" />
      <inertia
        ixx="1.42018834259434E-05"
        ixy="6.55738590279161E-10"
        ixz="3.44104879815956E-07"
        iyy="1.00733338221031E-05"
        iyz="-8.4376955023678E-10"
        izz="1.42018183774515E-05" />
    </inertial>
    <visual>
      <origin
        xyz="0 0 0"
        rpy="0 0 0" />
      <geometry>
        <mesh
          filename="package://new_humanoid1/meshes/right_shoulder_roll_link.stl" />
      </geometry>
      <material
        name="">
        <color
          rgba="0.792156862745098 0.819607843137255 0.933333333333333 1" />
      </material>
    </visual>
    <collision>
      <origin
        xyz="0 0 0"
        rpy="0 0 0" />
      <geometry>
        <mesh
          filename="package://new_humanoid1/meshes/right_shoulder_roll_link.stl" />
      </geometry>
    </collision>
  </link>
  <joint
    name="right_shoulder_roll_joint"
    type="continuous">
    <origin
      xyz="0.057897 -0.0091897 0.17689"
      rpy="1.5708 -0.019749 0" />
    <parent
      link="torso" />
    <child
      link="right_shoulder_roll_link" />
    <axis
      xyz="0 0 1" />
  </joint>
  <link
    name="right_shoulder_pitch_link">
    <inertial>
      <origin
        xyz="0.0552442355255676 5.93715609216797E-06 -6.09213908486783E-10"
        rpy="0 0 0" />
      <mass
        value="0.0745776007010866" />
      <inertia
        ixx="2.00988481516754E-05"
        ixy="2.77506650082917E-13"
        ixz="6.95503872890964E-12"
        iyy="3.48173971869422E-05"
        iyz="3.19702434946388E-13"
        izz="2.30395750860707E-05" />
    </inertial>
    <visual>
      <origin
        xyz="0 0 0"
        rpy="0 0 0" />
      <geometry>
        <mesh
          filename="package://new_humanoid1/meshes/right_shoulder_pitch_link.stl" />
      </geometry>
      <material
        name="">
        <color
          rgba="1 1 1 1" />
      </material>
    </visual>
    <collision>
      <origin
        xyz="0 0 0"
        rpy="0 0 0" />
      <geometry>
        <mesh
          filename="package://new_humanoid1/meshes/right_shoulder_pitch_link.stl" />
      </geometry>
    </collision>
  </link>
  <joint
    name="right_shoulder_pitch_joint"
    type="continuous">
    <origin
      xyz="0 -0.024 0.018"
      rpy="-1.5708 0.016927 -1.5708" />
    <parent
      link="right_shoulder_roll_link" />
    <child
      link="right_shoulder_pitch_link" />
    <axis
      xyz="0 0 1" />
  </joint>
  <link
    name="right_forearm_pitch_link">
    <inertial>
      <origin
        xyz="7.75844619807613E-05 -0.0331072828815372 0.000238558623536243"
        rpy="0 0 0" />
      <mass
        value="0.0942790394640175" />
      <inertia
        ixx="3.00632547327982E-05"
        ixy="1.02650366457583E-09"
        ixz="5.23892692999294E-09"
        iyy="1.67702181644344E-05"
        iyz="-2.55511629533334E-07"
        izz="3.34845379501349E-05" />
    </inertial>
    <visual>
      <origin
        xyz="0 0 0"
        rpy="0 0 0" />
      <geometry>
        <mesh
          filename="package://new_humanoid1/meshes/right_forearm_pitch_link.stl" />
      </geometry>
      <material
        name="">
        <color
          rgba="0.792156862745098 0.819607843137255 0.933333333333333 1" />
      </material>
    </visual>
    <collision>
      <origin
        xyz="0 0 0"
        rpy="0 0 0" />
      <geometry>
        <mesh
          filename="package://new_humanoid1/meshes/right_forearm_pitch_link.stl" />
      </geometry>
    </collision>
  </link>
  <joint
    name="right_forearm_pitch_joint"
    type="continuous">
    <origin
      xyz="0.11049 0 0"
      rpy="3.1416 0 -1.5811" />
    <parent
      link="right_shoulder_pitch_link" />
    <child
      link="right_forearm_pitch_link" />
    <axis
      xyz="0 0 1" />
  </joint>
  <link
    name="left_waist_roll_link">
    <inertial>
      <origin
        xyz="0.00060514328457334 -0.0120163616733306 0.0186305200305562"
        rpy="0 0 0" />
      <mass
        value="0.0517508412595708" />
      <inertia
        ixx="1.42018834260293E-05"
        ixy="6.55738462682621E-10"
        ixz="3.44104879705858E-07"
        iyy="1.00733338220756E-05"
        iyz="-8.43769425818299E-10"
        izz="1.42018183770993E-05" />
    </inertial>
    <visual>
      <origin
        xyz="0 0 0"
        rpy="0 0 0" />
      <geometry>
        <mesh
          filename="package://new_humanoid1/meshes/left_waist_roll_link.stl" />
      </geometry>
      <material
        name="">
        <color
          rgba="0.792156862745098 0.819607843137255 0.933333333333333 1" />
      </material>
    </visual>
    <collision>
      <origin
        xyz="0 0 0"
        rpy="0 0 0" />
      <geometry>
        <mesh
          filename="package://new_humanoid1/meshes/left_waist_roll_link.stl" />
      </geometry>
    </collision>
  </link>
  <joint
    name="left_waist_roll_joint"
    type="continuous">
    <origin
      xyz="0.22812 -0.0082528 0.025136"
      rpy="1.5708 -0.027515 0" />
    <parent
      link="torso" />
    <child
      link="left_waist_roll_link" />
    <axis
      xyz="0 0 1" />
  </joint>
  <link
    name="left_waist_pitch_link">
    <inertial>
      <origin
        xyz="4.98630990490578E-06 -0.0752442422125157 -1.31697236449568E-09"
        rpy="0 0 0" />
      <mass
        value="0.0888059448325319" />
      <inertia
        ixx="6.1539299136908E-05"
        ixy="-7.11709155767946E-13"
        ixz="4.87535746608038E-13"
        iyy="2.20093447975321E-05"
        iyz="-1.28530097694223E-11"
        izz="4.97614745034334E-05" />
    </inertial>
    <visual>
      <origin
        xyz="0 0 0"
        rpy="0 0 0" />
      <geometry>
        <mesh
          filename="package://new_humanoid1/meshes/left_waist_pitch_link.stl" />
      </geometry>
      <material
        name="">
        <color
          rgba="1 1 1 1" />
      </material>
    </visual>
    <collision>
      <origin
        xyz="0 0 0"
        rpy="0 0 0" />
      <geometry>
        <mesh
          filename="package://new_humanoid1/meshes/left_waist_pitch_link.stl" />
      </geometry>
    </collision>
  </link>
  <joint
    name="left_waist_pitch_joint"
    type="continuous">
    <origin
      xyz="0 -0.02400000035807 0.0180000000000001"
      rpy="1.5707963267949 1.5469076633424 1.57079632679489" />
    <parent
      link="left_waist_roll_link" />
    <child
      link="left_waist_pitch_link" />
    <axis
      xyz="0 0 1" />
  </joint>
  <link
    name="left_knee_pitch_link">
    <inertial>
      <origin
        xyz="0.000109196794509797 -0.0801720962559219 0.000134420161006871"
        rpy="0 0 0" />
      <mass
        value="0.167319145274048" />
      <inertia
        ixx="7.67196324477288E-05"
        ixy="1.03726465730852E-09"
        ixz="5.23861324240191E-09"
        iyy="3.31853028555169E-05"
        iyz="-2.55513058359107E-07"
        izz="8.01409185567005E-05" />
    </inertial>
    <visual>
      <origin
        xyz="0 0 0"
        rpy="0 0 0" />
      <geometry>
        <mesh
          filename="package://new_humanoid1/meshes/left_knee_pitch_link.stl" />
      </geometry>
      <material
        name="">
        <color
          rgba="0.792156862745098 0.819607843137255 0.933333333333333 1" />
      </material>
    </visual>
    <collision>
      <origin
        xyz="0 0 0"
        rpy="0 0 0" />
      <geometry>
        <mesh
          filename="package://new_humanoid1/meshes/left_knee_pitch_link.stl" />
      </geometry>
    </collision>
  </link>
  <joint
    name="left_knee_pitch_joint"
    type="continuous">
    <origin
      xyz="0 -0.150488463407201 0"
      rpy="-3.14159265358979 0 -3.09347494487016" />
    <parent
      link="left_waist_pitch_link" />
    <child
      link="left_knee_pitch_link" />
    <axis
      xyz="0 0 1" />
  </joint>
  <link
    name="right_waist_roll_link">
    <inertial>
      <origin
        xyz="0.000605143284644366 -0.0120163616733972 0.018630520030493"
        rpy="0 0 0" />
      <mass
        value="0.0517508412592891" />
      <inertia
        ixx="1.42018834259587E-05"
        ixy="6.55738448747096E-10"
        ixz="3.44104879705717E-07"
        iyy="1.00733338220598E-05"
        iyz="-8.43769395508812E-10"
        izz="1.42018183771059E-05" />
    </inertial>
    <visual>
      <origin
        xyz="0 0 0"
        rpy="0 0 0" />
      <geometry>
        <mesh
          filename="package://new_humanoid1/meshes/right_waist_roll_link.stl" />
      </geometry>
      <material
        name="">
        <color
          rgba="0.792156862745098 0.819607843137255 0.933333333333333 1" />
      </material>
    </visual>
    <collision>
      <origin
        xyz="0 0 0"
        rpy="0 0 0" />
      <geometry>
        <mesh
          filename="package://new_humanoid1/meshes/right_waist_roll_link.stl" />
      </geometry>
    </collision>
  </link>
  <joint
    name="right_waist_roll_joint"
    type="continuous">
    <origin
      xyz="0.14312 -0.0082528 0.025136"
      rpy="1.5708 0.0071787 0" />
    <parent
      link="torso" />
    <child
      link="right_waist_roll_link" />
    <axis
      xyz="0 0 1" />
  </joint>
  <link
    name="right_waist_pitch_link">
    <inertial>
      <origin
        xyz="4.98626618483655E-06 -0.0752442426541142 -1.53468895924824E-09"
        rpy="0 0 0" />
      <mass
        value="0.0888059524886223" />
      <inertia
        ixx="6.15393014318827E-05"
        ixy="-5.30337837519573E-13"
        ixz="4.84560599499836E-13"
        iyy="2.20093457146995E-05"
        iyz="-1.57732305783025E-11"
        izz="4.97614763315345E-05" />
    </inertial>
    <visual>
      <origin
        xyz="0 0 0"
        rpy="0 0 0" />
      <geometry>
        <mesh
          filename="package://new_humanoid1/meshes/right_waist_pitch_link.stl" />
      </geometry>
      <material
        name="">
        <color
          rgba="1 1 1 1" />
      </material>
    </visual>
    <collision>
      <origin
        xyz="0 0 0"
        rpy="0 0 0" />
      <geometry>
        <mesh
          filename="package://new_humanoid1/meshes/right_waist_pitch_link.stl" />
      </geometry>
    </collision>
  </link>
  <joint
    name="right_waist_pitch_joint"
    type="continuous">
    <origin
      xyz="0 -0.024 0.018"
      rpy="1.5708 1.5153 1.5708" />
    <parent
      link="right_waist_roll_link" />
    <child
      link="right_waist_pitch_link" />
    <axis
      xyz="0 0 1" />
  </joint>
  <link
    name="right_knee_pitch_link">
    <inertial>
      <origin
        xyz="0.000109196869023987 -0.0801720964370397 0.000134420195484986"
        rpy="0 0 0" />
      <mass
        value="0.167319144912029" />
      <inertia
        ixx="7.67196325811071E-05"
        ixy="1.03751007848743E-09"
        ixz="5.23876536021814E-09"
        iyy="3.31853027285061E-05"
        iyz="-2.55513046908669E-07"
        izz="8.01409187284783E-05" />
    </inertial>
    <visual>
      <origin
        xyz="0 0 0"
        rpy="0 0 0" />
      <geometry>
        <mesh
          filename="package://new_humanoid1/meshes/right_knee_pitch_link.stl" />
      </geometry>
      <material
        name="">
        <color
          rgba="0.792156862745098 0.819607843137255 0.933333333333333 1" />
      </material>
    </visual>
    <collision>
      <origin
        xyz="0 0 0"
        rpy="0 0 0" />
      <geometry>
        <mesh
          filename="package://new_humanoid1/meshes/right_knee_pitch_link.stl" />
      </geometry>
    </collision>
  </link>
  <joint
    name="right_knee_pitch_joint"
    type="continuous">
    <origin
      xyz="0 -0.15049 0"
      rpy="3.1416 0 3.1238" />
    <parent
      link="right_waist_pitch_link" />
    <child
      link="right_knee_pitch_link" />
    <axis
      xyz="0 0 1" />
  </joint>
</robot>