<?xml version="1.0" ?>
<robot name="new_humanoid1">
   <link name="world"/>
   
   <link name="floating_base">
      <inertial>
         <origin xyz="0 0 0" rpy="0 0 0"/>
         <mass value="1"/>
         <inertia ixx="0.01" ixy="0" ixz="0" iyy="0.01" iyz="0" izz="0.01"/>
      </inertial>
   </link>

   <joint name="floating_joint" type="floating">
      <parent link="world"/>
      <child link="floating_base"/>
   </joint>

   
  <!-- Floor link -->
  <link name="floor">
    <visual>
      <origin xyz="0 0 0" rpy="0 0 0"/>
      <geometry>
        <box size="100 100 0.1"/> <!-- A large flat box representing the floor -->
      </geometry>
      <material name="gray">
        <color rgba="0.5 0.5 0.5 1.0"/>
      </material>
    </visual>
    <collision>
      <origin xyz="0 0 0" rpy="0 0 0"/>
      <geometry>
        <box size="100 100 0.01"/>
      </geometry>
    </collision>
  </link>

  <!-- Fixed joint to anchor the floor -->
  <joint name="fixed_floor" type="fixed">
    <parent link="world"/>
    <child link="floor"/>
    <origin xyz="0 0 -0.375" rpy="0 0 0"/> <!-- Slightly below z=0 -->
  </joint>

   <link name="humanoid_world_link">
      <inertial>
         <origin xyz="0.0 0.0 -0.385" rpy="0.0 0.0 -1.5707963267948957"/>
         <mass value="0.0"/>
         <inertia ixx="0.0" iyy="0.0" izz="0.0" ixy="0" ixz="0" iyz="0"/>
      </inertial>
   </link>

   <joint name="floating_base_to_humanoid" type="fixed">
      <parent link="floating_base"/>
      <child link="humanoid_world_link"/>
      <origin xyz="0 0 0" rpy="0 0 0"/>
   </joint>
   <link name="humanoid">
      <inertial>
         <origin xyz="0.0 0.0 0.0" rpy="0.0 0.0 1.5707963267948963"/>
         <mass value="0.0"/>
         <inertia ixx="0.0" iyy="0.0" izz="0.0" ixy="0" ixz="0" iyz="0"/>
      </inertial>
   </link>
   <link name="humanoid_world_link2humanoid_fixed_jointbody">
      <inertial>
         <origin xyz="0.0 0.0 0.0" rpy="0.0 0.0 0.0"/>
         <mass value="0.001"/>
         <inertia ixx="1e-09" iyy="1e-09" izz="1e-09" ixy="0" ixz="0" iyz="0"/>
      </inertial>
   </link>
   <joint type="fixed" name="humanoid_world_link2humanoid_fixed">
      <parent link="humanoid_world_link"/>
      <child link="humanoid_world_link2humanoid_fixed_jointbody"/>
      <origin xyz="0.0 0.0 0.0" rpy="0.0 0.0 1.5707963267948963"/>
   </joint>
   <joint type="fixed" name="humanoid_world_link2humanoid_fixed_offset">
      <parent link="humanoid_world_link2humanoid_fixed_jointbody"/>
      <child link="humanoid"/>
      <origin xyz="-0.0 -0.0 -0.0" rpy="0.0 0.0 0.0"/>
   </joint>
   <link name="torso">
      <inertial>
         <origin xyz="0.1848149436815727 -0.003939209452785282 0.1110067214511154" rpy="-0.0008201436182088129 -0.12382311655719636 1.5628008270149865"/>
         <mass value="3.4308131130467148"/>
         <inertia ixx="0.010527741038321506" iyy="0.009364184382386672" izz="0.004851735924892816" ixy="0" ixz="0" iyz="0"/>
      </inertial>
      <visual name="torso">
         <origin xyz="0.1848149436815727 -0.003939209452785282 0.1110067214511154" rpy="-0.0008201436182088129 -0.12382311655719636 1.5628008270149865"/>
         <geometry>
            <mesh filename="/root/Humanoid-MuJoCo-Inverse-Dynamics/id_urdf/converted_torso.stl"/>
         </geometry>
         <material name="white"/>
      </visual>
      <collision>
         <origin xyz="0.1848149436815727 -0.003939209452785282 0.1110067214511154" rpy="-0.0008201436182088129 -0.12382311655719636 1.5628008270149865"/>
         <geometry>
            <mesh filename="/root/Humanoid-MuJoCo-Inverse-Dynamics/id_urdf/converted_torso.stl"/> <!-- Same mesh for collision -->
         </geometry>
      </collision>
   </link>
   <link name="humanoid_world_link2torso_fixed_jointbody">
      <inertial>
         <origin xyz="0.0 0.0 0.0" rpy="0.0 0.0 0.0"/>
         <mass value="0.001"/>
         <inertia ixx="1e-09" iyy="1e-09" izz="1e-09" ixy="0" ixz="0" iyz="0"/>
      </inertial>
   </link>
   <joint type="fixed" name="humanoid_world_link2torso_fixed">
      <parent link="humanoid_world_link"/>
      <child link="humanoid_world_link2torso_fixed_jointbody"/>
      <origin xyz="0.0 0.0 0.0" rpy="0.0 0.0 0.0"/>
   </joint>
   <joint type="fixed" name="humanoid_world_link2torso_fixed_offset">
      <parent link="humanoid_world_link2torso_fixed_jointbody"/>
      <child link="torso"/>
      <origin xyz="-0.0 -0.0 -0.0" rpy="0.0 0.0 0.0"/>
   </joint>
   <link name="right_shoulder_roll_link">
      <inertial>
         <origin xyz="0.000605694 -0.0120164 0.0186305" rpy="1.5711056143805455 -0.7853510112428619 -4.085155188793266e-05"/>
         <mass value="0.0517508"/>
         <inertia ixx="1.4546e-05" iyy="1.38577e-05" izz="1.00733e-05" ixy="0" ixz="0" iyz="0"/>
      </inertial>
   </link>
   <link name="right_shoulder_roll_jointbody">
      <inertial>
         <origin xyz="0.0 0.0 0.0" rpy="0.0 0.0 0.0"/>
         <mass value="0.001"/>
         <inertia ixx="1e-09" iyy="1e-09" izz="1e-09" ixy="0" ixz="0" iyz="0"/>
      </inertial>
   </link>
   <joint type="revolute" name="right_shoulder_roll">
      <parent link="humanoid_world_link"/>
      <child link="right_shoulder_roll_jointbody"/>
      <origin xyz="0.31335 -0.0091897 0.17689" rpy="1.5707991552227036 -0.0027388012397646655 1.7836072618848675e-09"/>
      <axis xyz="0.0 0.0 -1.0"/>
      <limit lower="-1.5708" upper="0.0" effort="100" velocity="100"/>
   </joint>
   <joint type="fixed" name="right_shoulder_roll_offset">
      <parent link="right_shoulder_roll_jointbody"/>
      <child link="right_shoulder_roll_link"/>
      <origin xyz="-0.0 -0.0 -0.0" rpy="0.0 0.0 0.0"/>
   </joint>
   <link name="right_shoulder_pitch_link">
      <inertial>
         <origin xyz="-5.93785e-06 -0.0552442 -1.9163e-10" rpy="1.5707963267948963 0.0 0.0"/>
         <mass value="0.0745776"/>
         <inertia ixx="3.48174e-05" iyy="2.30396e-05" izz="2.00988e-05" ixy="0" ixz="0" iyz="0"/>
      </inertial>
      <visual name="left_shoulder_pitch_link">
         <origin xyz="6.170213679797289e-06 -0.04811005516614877 0.0004259767121680248" rpy="1.5723736055119883 0.0004308432514816829 -0.0030158063311287453"/>
         <geometry>
            <mesh filename="/root/Humanoid-MuJoCo-Inverse-Dynamics/id_urdf/converted_left_shoulder_pitch_link.stl"/>
         </geometry>
         <material name="white"/>
      </visual>
      <collision>
         <origin xyz="6.170213679797289e-06 -0.04811005516614877 0.0004259767121680248" rpy="1.5723736055119883 0.0004308432514816829 -0.0030158063311287453"/>
         <geometry>
            <mesh filename="/root/Humanoid-MuJoCo-Inverse-Dynamics/id_urdf/converted_left_shoulder_pitch_link.stl"/> <!-- Same mesh for collision -->
         </geometry>
      </collision>
   </link>
   <link name="right_shoulder_pitch_jointbody">
      <inertial>
         <origin xyz="0.0 0.0 0.0" rpy="0.0 0.0 0.0"/>
         <mass value="0.001"/>
         <inertia ixx="1e-09" iyy="1e-09" izz="1e-09" ixy="0" ixz="0" iyz="0"/>
      </inertial>
   </link>
   <joint type="revolute" name="right_shoulder_pitch">
      <parent link="right_shoulder_roll_link"/>
      <child link="right_shoulder_pitch_jointbody"/>
      <origin xyz="0.0 -0.024 0.018" rpy="1.5707963267948966 -1.5121998783022097 -1.5707963267948966"/>
      <axis xyz="0.0 0.0 1.0"/>
      <limit lower="-1.5708" upper="1.5708" effort="100" velocity="100"/>
   </joint>
   <joint type="fixed" name="right_shoulder_pitch_offset">
      <parent link="right_shoulder_pitch_jointbody"/>
      <child link="right_shoulder_pitch_link"/>
      <origin xyz="-0.0 -0.0 -0.0" rpy="0.0 0.0 0.0"/>
   </joint>
   <link name="right_forearm_pitch_link">
      <inertial>
         <origin xyz="0.000238558 -0.0331073 8.27912e-05" rpy="1.570880845012051 0.0015247599963423841 -0.015282277012447443"/>
         <mass value="0.094279"/>
         <inertia ixx="3.34885e-05" iyy="3.00632e-05" izz="1.67663e-05" ixy="0" ixz="0" iyz="0"/>
      </inertial>
      <visual name="left_forearm_pitch_link">
         <origin xyz="-0.0015062228052955852 -0.032047491907380175 -0.00014188468516069193" rpy="1.5654157737443342 -0.0070283882358512795 0.03136689956316363"/>
         <geometry>
            <mesh filename="/root/Humanoid-MuJoCo-Inverse-Dynamics/id_urdf/converted_left_forearm_pitch_link.stl"/>
         </geometry>
         <material name="white"/>
      </visual>
      <collision>
         <origin xyz="-0.0015062228052955852 -0.032047491907380175 -0.00014188468516069193" rpy="1.5654157737443342 -0.0070283882358512795 0.03136689956316363"/>
         <geometry>
            <mesh filename="/root/Humanoid-MuJoCo-Inverse-Dynamics/id_urdf/converted_left_shoulder_pitch_link.stl"/> <!-- Same mesh for collision -->
         </geometry>
      </collision>
   </link>
   <link name="right_elbow_jointbody">
      <inertial>
         <origin xyz="0.0 0.0 0.0" rpy="0.0 0.0 0.0"/>
         <mass value="0.001"/>
         <inertia ixx="1e-09" iyy="1e-09" izz="1e-09" ixy="0" ixz="0" iyz="0"/>
      </inertial>
   </link>
   <joint type="revolute" name="right_elbow">
      <parent link="right_shoulder_pitch_link"/>
      <child link="right_elbow_jointbody"/>
      <origin xyz="0.0 -0.11049 0.0" rpy="-0.6683787225602067 -1.5707927570321976 0.6439787134901467"/>
      <axis xyz="1.0 0.0 0.0"/>
      <limit lower="-1.5708" upper="0.0" effort="100" velocity="100"/>
   </joint>
   <joint type="fixed" name="right_elbow_offset">
      <parent link="right_elbow_jointbody"/>
      <child link="right_forearm_pitch_link"/>
      <origin xyz="-0.0 -0.0 -0.0" rpy="0.0 0.0 0.0"/>
   </joint>
   <link name="left_shoulder_roll_link">
      <inertial>
         <origin xyz="0.000605694 -0.0120164 0.0186305" rpy="1.5711056143805455 -0.7853510112428619 -4.085155188793266e-05"/>
         <mass value="0.0517508"/>
         <inertia ixx="1.4546e-05" iyy="1.38577e-05" izz="1.00733e-05" ixy="0" ixz="0" iyz="0"/>
      </inertial>
   </link>
   <link name="left_shoulder_roll_jointbody">
      <inertial>
         <origin xyz="0.0 0.0 0.0" rpy="0.0 0.0 0.0"/>
         <mass value="0.001"/>
         <inertia ixx="1e-09" iyy="1e-09" izz="1e-09" ixy="0" ixz="0" iyz="0"/>
      </inertial>
   </link>
   <joint type="revolute" name="left_shoulder_roll">
      <parent link="humanoid_world_link"/>
      <child link="left_shoulder_roll_jointbody"/>
      <origin xyz="0.057897 -0.0091897 0.17689" rpy="1.5707991552227036 -0.0027388012397646655 1.7836072618848675e-09"/>
      <axis xyz="0.0 0.0 -1.0"/>
      <limit lower="0.0" upper="1.5708" effort="100" velocity="100"/>
   </joint>
   <joint type="fixed" name="left_shoulder_roll_offset">
      <parent link="left_shoulder_roll_jointbody"/>
      <child link="left_shoulder_roll_link"/>
      <origin xyz="-0.0 -0.0 -0.0" rpy="0.0 0.0 0.0"/>
   </joint>
   <link name="left_shoulder_pitch_link">
      <inertial>
         <origin xyz="-5.93785e-06 -0.0552442 -1.9163e-10" rpy="1.5707963267948963 0.0 0.0"/>
         <mass value="0.0745776"/>
         <inertia ixx="3.48174e-05" iyy="2.30396e-05" izz="2.00988e-05" ixy="0" ixz="0" iyz="0"/>
      </inertial>
      <visual name="left_shoulder_pitch_link">
         <origin xyz="6.170213679797289e-06 -0.04811005516614877 0.0004259767121680248" rpy="1.5723736055119883 0.0004308432514816829 -0.0030158063311287453"/>
         <geometry>
            <mesh filename="/root/Humanoid-MuJoCo-Inverse-Dynamics/id_urdf/converted_left_shoulder_pitch_link.stl"/>
         </geometry>
         <material name="white"/>
      </visual>
      <collision>
         <origin xyz="6.170213679797289e-06 -0.04811005516614877 0.0004259767121680248" rpy="1.5723736055119883 0.0004308432514816829 -0.0030158063311287453"/>
         <geometry>
            <mesh filename="/root/Humanoid-MuJoCo-Inverse-Dynamics/id_urdf/converted_left_shoulder_pitch_link.stl"/> <!-- Same mesh for collision -->
         </geometry>
      </collision>
   </link>
   <link name="left_shoulder_pitch_jointbody">
      <inertial>
         <origin xyz="0.0 0.0 0.0" rpy="0.0 0.0 0.0"/>
         <mass value="0.001"/>
         <inertia ixx="1e-09" iyy="1e-09" izz="1e-09" ixy="0" ixz="0" iyz="0"/>
      </inertial>
   </link>
   <joint type="revolute" name="left_shoulder_pitch">
      <parent link="left_shoulder_roll_link"/>
      <child link="left_shoulder_pitch_jointbody"/>
      <origin xyz="0.0 -0.024 0.018" rpy="1.5707963267948966 -1.5121998783022097 -1.5707963267948966"/>
      <axis xyz="0.0 0.0 1.0"/>
      <limit lower="-1.5708" upper="1.5708" effort="100" velocity="100"/>
   </joint>
   <joint type="fixed" name="left_shoulder_pitch_offset">
      <parent link="left_shoulder_pitch_jointbody"/>
      <child link="left_shoulder_pitch_link"/>
      <origin xyz="-0.0 -0.0 -0.0" rpy="0.0 0.0 0.0"/>
   </joint>
   <link name="left_forearm_pitch_link">
      <inertial>
         <origin xyz="0.000238558 -0.0331073 8.27912e-05" rpy="1.570880845012051 0.0015247599963423841 -0.015282277012447443"/>
         <mass value="0.094279"/>
         <inertia ixx="3.34885e-05" iyy="3.00632e-05" izz="1.67663e-05" ixy="0" ixz="0" iyz="0"/>
      </inertial>
      <visual name="left_forearm_pitch_link">
         <origin xyz="-0.0015062228052955852 -0.032047491907380175 -0.00014188468516069193" rpy="1.5654157737443342 -0.0070283882358512795 0.03136689956316363"/>
         <geometry>
            <mesh filename="/root/Humanoid-MuJoCo-Inverse-Dynamics/id_urdf/converted_left_forearm_pitch_link.stl"/>
         </geometry>
         <material name="white"/>
      </visual>
      <collision>
         <origin xyz="-0.0015062228052955852 -0.032047491907380175 -0.00014188468516069193" rpy="1.5654157737443342 -0.0070283882358512795 0.03136689956316363"/>
         <geometry>
            <mesh filename="/root/Humanoid-MuJoCo-Inverse-Dynamics/id_urdf/converted_left_forearm_pitch_link.stl"/> <!-- Same mesh for collision -->
         </geometry>
      </collision>
   </link>
   <link name="left_elbow_jointbody">
      <inertial>
         <origin xyz="0.0 0.0 0.0" rpy="0.0 0.0 0.0"/>
         <mass value="0.001"/>
         <inertia ixx="1e-09" iyy="1e-09" izz="1e-09" ixy="0" ixz="0" iyz="0"/>
      </inertial>
   </link>
   <joint type="revolute" name="left_elbow">
      <parent link="left_shoulder_pitch_link"/>
      <child link="left_elbow_jointbody"/>
      <origin xyz="0.0 -0.11049 0.0" rpy="-0.6683787225602067 -1.5707927570321976 0.6439787134901467"/>
      <axis xyz="1.0 0.0 0.0"/>
      <limit lower="-1.5708" upper="0.0" effort="100" velocity="100"/>
   </joint>
   <joint type="fixed" name="left_elbow_offset">
      <parent link="left_elbow_jointbody"/>
      <child link="left_forearm_pitch_link"/>
      <origin xyz="-0.0 -0.0 -0.0" rpy="0.0 0.0 0.0"/>
   </joint>
   <link name="right_waist_roll_link">
      <inertial>
         <origin xyz="0.000605143 -0.0120164 0.0186305" rpy="1.5711056143805455 -0.7853510112428619 -4.085155188793266e-05"/>
         <mass value="0.0517508"/>
         <inertia ixx="1.4546e-05" iyy="1.38577e-05" izz="1.00733e-05" ixy="0" ixz="0" iyz="0"/>
      </inertial>
   </link>
   <link name="right_hip_roll_jointbody">
      <inertial>
         <origin xyz="0.0 0.0 0.0" rpy="0.0 0.0 0.0"/>
         <mass value="0.001"/>
         <inertia ixx="1e-09" iyy="1e-09" izz="1e-09" ixy="0" ixz="0" iyz="0"/>
      </inertial>
   </link>
   <joint type="revolute" name="right_hip_roll">
      <parent link="humanoid_world_link"/>
      <child link="right_hip_roll_jointbody"/>
      <origin xyz="0.22812 -0.0082528 0.025136" rpy="1.5707991554408403 -0.027514995685623767 3.5128683295582164e-09"/>
      <axis xyz="0.0 0.0 -1.0"/>
      <limit lower="-1.5708" upper="0.0" effort="100" velocity="100"/>
   </joint>
   <joint type="fixed" name="right_hip_roll_offset">
      <parent link="right_hip_roll_jointbody"/>
      <child link="right_waist_roll_link"/>
      <origin xyz="-0.0 -0.0 -0.0" rpy="0.0 0.0 0.0"/>
   </joint>
   <link name="right_waist_pitch_link">
      <inertial>
         <origin xyz="4.98631e-06 -0.0752442 -1.31697e-09" rpy="1.5707963267948963 0.0 0.0"/>
         <mass value="0.0888059"/>
         <inertia ixx="6.15393e-05" iyy="4.97615e-05" izz="2.20093e-05" ixy="0" ixz="0" iyz="0"/>
      </inertial>
      <visual name="left_waist_pitch_link">
         <origin xyz="3.4735342078596717e-05 -0.07509646779447576 0.000293067029352159" rpy="1.5755494080362866 0.018640632383124967 0.003988221086784871"/>
         <geometry>
            <mesh filename="/root/Humanoid-MuJoCo-Inverse-Dynamics/id_urdf/converted_left_waist_pitch_link.stl"/>
         </geometry>
         <material name="white"/>
      </visual>
      <collision>
         <origin xyz="3.4735342078596717e-05 -0.07509646779447576 0.000293067029352159" rpy="1.5755494080362866 0.018640632383124967 0.003988221086784871"/>
         <geometry>
            <mesh filename="/root/Humanoid-MuJoCo-Inverse-Dynamics/id_urdf/converted_left_waist_pitch_link.stl"/> <!-- Same mesh for collision -->
         </geometry>
      </collision>
   </link>
   <link name="right_hip_pitch_jointbody">
      <inertial>
         <origin xyz="0.0 0.0 0.0" rpy="0.0 0.0 0.0"/>
         <mass value="0.001"/>
         <inertia ixx="1e-09" iyy="1e-09" izz="1e-09" ixy="0" ixz="0" iyz="0"/>
      </inertial>
   </link>
   <joint type="revolute" name="right_hip_pitch">
      <parent link="right_waist_roll_link"/>
      <child link="right_hip_pitch_jointbody"/>
      <origin xyz="0.0 -0.024 0.018" rpy="1.5707963267948901 1.5469076437103753 1.5707963267948901"/>
      <axis xyz="0.0 0.0 -1.0"/>
      <limit lower="-1.5708" upper="1.5708" effort="100" velocity="100"/>
   </joint>
   <joint type="fixed" name="right_hip_pitch_offset">
      <parent link="right_hip_pitch_jointbody"/>
      <child link="right_waist_pitch_link"/>
      <origin xyz="-0.0 -0.0 -0.0" rpy="0.0 0.0 0.0"/>
   </joint>
   <link name="right_knee_pitch_link">
      <inertial>
         <origin xyz="0.000109197 -0.0801721 0.00013442" rpy="2.867657935046832 -1.5651445681714782 -1.2968326081504364"/>
         <mass value="0.167319"/>
         <inertia ixx="8.01423e-05" iyy="7.67196e-05" izz="3.31839e-05" ixy="0" ixz="0" iyz="0"/>
      </inertial>
      <visual name="left_knee_pitch_link">
         <origin xyz="2.4942481063558257e-05 -0.06642470209627441 -0.0008937530860745312" rpy="-1.4965830467200827 -1.338702254587331 3.0687391559110737"/>
         <geometry>
            <mesh filename="/root/Humanoid-MuJoCo-Inverse-Dynamics/id_urdf/converted_left_knee_pitch_link.stl"/>
         </geometry>
         <material name="white"/>
      </visual>
      <collision>
         <origin xyz="2.4942481063558257e-05 -0.06642470209627441 -0.0008937530860745312" rpy="-1.4965830467200827 -1.338702254587331 3.0687391559110737"/>
         <geometry>
            <mesh filename="/root/Humanoid-MuJoCo-Inverse-Dynamics/id_urdf/converted_left_knee_pitch_link.stl"/> <!-- Same mesh for collision -->
         </geometry>
      </collision>
   </link>
   <link name="right_knee_jointbody">
      <inertial>
         <origin xyz="0.0 0.0 0.0" rpy="0.0 0.0 0.0"/>
         <mass value="0.001"/>
         <inertia ixx="1e-09" iyy="1e-09" izz="1e-09" ixy="0" ixz="0" iyz="0"/>
      </inertial>
   </link>
   <joint type="revolute" name="right_knee">
      <parent link="right_waist_pitch_link"/>
      <child link="right_knee_jointbody"/>
      <origin xyz="0.0 -0.150488 0.0" rpy="3.1415926535897927 0.0 -3.0934750309799797"/>
      <axis xyz="0.0 0.0 1.0"/>
      <limit lower="0.0" upper="1.5708" effort="100" velocity="100"/>
   </joint>
   <joint type="fixed" name="right_knee_offset">
      <parent link="right_knee_jointbody"/>
      <child link="right_knee_pitch_link"/>
      <origin xyz="-0.0 -0.0 -0.0" rpy="0.0 0.0 0.0"/>
   </joint>
   <link name="left_waist_roll_link">
      <inertial>
         <origin xyz="0.000605143 -0.0120164 0.0186305" rpy="1.5711056143805455 -0.7853510112428619 -4.085155188793266e-05"/>
         <mass value="0.0517508"/>
         <inertia ixx="1.4546e-05" iyy="1.38577e-05" izz="1.00733e-05" ixy="0" ixz="0" iyz="0"/>
      </inertial>
   </link>
   <link name="left_hip_roll_jointbody">
      <inertial>
         <origin xyz="0.0 0.0 0.0" rpy="0.0 0.0 0.0"/>
         <mass value="0.001"/>
         <inertia ixx="1e-09" iyy="1e-09" izz="1e-09" ixy="0" ixz="0" iyz="0"/>
      </inertial>
   </link>
   <joint type="revolute" name="left_hip_roll">
      <parent link="humanoid_world_link"/>
      <child link="left_hip_roll_jointbody"/>
      <origin xyz="0.14312 -0.0082528 0.025136" rpy="1.5708005694651699 0.007178687956692409 1.0862470922745615e-09"/>
      <axis xyz="0.0 0.0 -1.0"/>
      <limit lower="0.0" upper="1.5708" effort="100" velocity="100"/>
   </joint>
   <joint type="fixed" name="left_hip_roll_offset">
      <parent link="left_hip_roll_jointbody"/>
      <child link="left_waist_roll_link"/>
      <origin xyz="-0.0 -0.0 -0.0" rpy="0.0 0.0 0.0"/>
   </joint>
   <link name="left_waist_pitch_link">
      <inertial>
         <origin xyz="4.98627e-06 -0.0752442 -1.53469e-09" rpy="1.5707963267948963 0.0 0.0"/>
         <mass value="0.088806"/>
         <inertia ixx="6.15393e-05" iyy="4.97615e-05" izz="2.20093e-05" ixy="0" ixz="0" iyz="0"/>
      </inertial>
      <visual name="right_waist_pitch_link">
         <origin xyz="6.343753114682828e-05 -0.07464215283845539 -0.00022095380771330498" rpy="1.580042344948899 0.0008422375586811803 -0.0003055465525159118"/>
         <geometry>
            <mesh filename="/root/Humanoid-MuJoCo-Inverse-Dynamics/id_urdf/converted_right_waist_pitch_link.stl"/>
         </geometry>
         <material name="white"/>
      </visual>
      <collision>
         <origin xyz="6.343753114682828e-05 -0.07464215283845539 -0.00022095380771330498" rpy="1.580042344948899 0.0008422375586811803 -0.0003055465525159118"/>
         <geometry>
            <mesh filename="/root/Humanoid-MuJoCo-Inverse-Dynamics/id_urdf/converted_right_waist_pitch_link.stl"/> <!-- Same mesh for collision -->
         </geometry>
      </collision>
   </link>
   <link name="left_hip_pitch_jointbody">
      <inertial>
         <origin xyz="0.0 0.0 0.0" rpy="0.0 0.0 0.0"/>
         <mass value="0.001"/>
         <inertia ixx="1e-09" iyy="1e-09" izz="1e-09" ixy="0" ixz="0" iyz="0"/>
      </inertial>
   </link>
   <joint type="revolute" name="left_hip_pitch">
      <parent link="left_waist_roll_link"/>
      <child link="left_hip_pitch_jointbody"/>
      <origin xyz="0.0 -0.024 0.018" rpy="1.5707963267948966 1.5153000239395658 1.5707963267948966"/>
      <axis xyz="0.0 0.0 -1.0"/>
      <limit lower="-1.5708" upper="1.5708" effort="100" velocity="100"/>
   </joint>
   <joint type="fixed" name="left_hip_pitch_offset">
      <parent link="left_hip_pitch_jointbody"/>
      <child link="left_waist_pitch_link"/>
      <origin xyz="-0.0 -0.0 -0.0" rpy="0.0 0.0 0.0"/>
   </joint>
   <link name="left_knee_pitch_link">
      <inertial>
         <origin xyz="0.000109197 -0.0801721 0.00013442" rpy="2.867657935046832 -1.5651445681714782 -1.2968326081504364"/>
         <mass value="0.167319"/>
         <inertia ixx="8.01423e-05" iyy="7.67196e-05" izz="3.31839e-05" ixy="0" ixz="0" iyz="0"/>
      </inertial>
      <visual name="right_knee_pitch_link">
         <origin xyz="2.4948693932594023e-05 -0.06642495789247539 -0.0008938463733803115" rpy="-1.4965465703885203 -1.3388865249809943 3.068699887912389"/>
         <geometry>
            <mesh filename="/root/Humanoid-MuJoCo-Inverse-Dynamics/id_urdf/converted_right_knee_pitch_link.stl"/>
         </geometry>
         <material name="white"/>
      </visual>
      <collision>
         <origin xyz="2.4948693932594023e-05 -0.06642495789247539 -0.0008938463733803115" rpy="-1.4965465703885203 -1.3388865249809943 3.068699887912389"/>
         <geometry>
            <mesh filename="/root/Humanoid-MuJoCo-Inverse-Dynamics/id_urdf/converted_right_knee_pitch_link.stl"/> <!-- Same mesh for collision -->
         </geometry>
      </collision>
   </link>
   <link name="left_knee_jointbody">
      <inertial>
         <origin xyz="0.0 0.0 0.0" rpy="0.0 0.0 0.0"/>
         <mass value="0.001"/>
         <inertia ixx="1e-09" iyy="1e-09" izz="1e-09" ixy="0" ixz="0" iyz="0"/>
      </inertial>
   </link>
   <joint type="revolute" name="left_knee">
      <parent link="left_waist_pitch_link"/>
      <child link="left_knee_jointbody"/>
      <origin xyz="0.0 -0.15049 0.0" rpy="-3.1415853071759368 4.04121180963557e-14 3.1237999912777394"/>
      <axis xyz="0.0 0.0 1.0"/>
      <limit lower="0.0" upper="1.5708" effort="100" velocity="100"/>
   </joint>
   <joint type="fixed" name="left_knee_offset">
      <parent link="left_knee_jointbody"/>
      <child link="left_knee_pitch_link"/>
      <origin xyz="-0.0 -0.0 -0.0" rpy="0.0 0.0 0.0"/>
   </joint>
   <material name="white">
      <color rgba="1 1 1 1"/>
   </material>
</robot>
